Workbook

Sheet l_cons
A1: consId | B1: name | C1: dimension | D1: unit | E1: Molar mass [g/mol]
A3: unknown_elements | B3: unknown_elements | C3: mass | D3: kg
A4: C | B4: Carbon | C4: mass | D4: kg | E4: 12.011 | T4: 1
A5: Ca | B5: Calcium | C5: mass | D5: kg | E5: 40.078
A6: Cl | B6: Chlorine | C6: mass | D6: kg | E6: 35.453
A7: F | B7: Fluorine | C7: mass | D7: kg | E7: 18.998
A8: H | B8: Hydrogen | C8: mass | D8: kg | E8: 1.007
A9: K | B9: Potassium | C9: mass | D9: kg | E9: 39.098
A10: N | B10: Nitrogen | C10: mass | D10: kg | E10: 14.007
A11: Na | B11: Sodium | C11: mass | D11: kg | E11: 22.99
A12: O | B12: Oxygen | C12: mass | D12: kg | E12: 15.999
A13: P | B13: Phosphorus | C13: mass | D13: kg | E13: 30.974
A14: S | B14: Sulfur | C14: mass | D14: kg | E14: 32.065
A15: Ag | B15: Silver | C15: mass | D15: kg | E15: 107.868
A16: Al | B16: Aluminum | C16: mass | D16: kg | E16: 26.982
... A121: Og | B121: Oganesson | C121: mass | D121: kg | E121: 294
A124: =IF(B124=0,"",B124)
A125: =IF(B125=0,"",B125)
A126: =IF(B126=0,"",B126)
A127: =IF(B127=0,"",B127)
A128: =IF(B128=0,"",B128)
A129: =IF(B129=0,"",B129)
A130: =IF(B130=0,"",B130)
A131: =IF(B131=0,"",B131)
A132: =IF(B132=0,"",B132)
A133: =IF(B133=0,"",B133)
A134: =IF(B134=0,"",B134)
A135: =IF(B135=0,"",B135)
... A203: =IF(B203=0,"",B203)

Sheet l_trans
A1: id | B1: name | C1: reference_property | D1: unit | E1: Distinction
A3: CO2 | B3: Carbon dioxyde | C3: mass | D3: kg
A4: CH4 | B4: methane | C4: mass | D4: kg
A5: C n.e.s. | B5: other carbon | C5: mass | D5: kg | E5: n.e.s.
A6: =IF(B6=0,F18,_xlfn.CONCAT(B6,IF(E6="", ," " ),E6 )) -> C_bio | B6: C_bio | C6: mass | D6: kg
A7: =IF(B7=0,F19,_xlfn.CONCAT(B7,IF(E7="", ," " ),E7 )) -> C_fossil | B7: C_fossil | C7: mass | D7: kg
A8: =IF(B8=0,F20,_xlfn.CONCAT(B8,IF(E8="", ," " ),E8 )) -> Ca n.e.s. | B8: Ca | C8: mass | D8: kg | E8: n.e.s.
A9: =IF(B9=0,F21,_xlfn.CONCAT(B9,IF(E9="", ," " ),E9 )) -> Cl n.e.s. | B9: Cl | C9: mass | D9: kg | E9: n.e.s.
A10: =IF(B10=0,F22,_xlfn.CONCAT(B10,IF(E10="", ," " ),E10 )) -> F n.e.s. | B10: F | C10: mass | D10: kg | E10: n.e.s.
A11: =IF(B11=0,F23,_xlfn.CONCAT(B11,IF(E11="", ," " ),E11 )) -> H n.e.s. | B11: H | C11: mass | D11: kg | E11: n.e.s.
A12: =IF(B12=0,F24,_xlfn.CONCAT(B12,IF(E12="", ," " ),E12 )) -> K n.e.s. | B12: K | C12: mass | D12: kg | E12: n.e.s.
A13: =IF(B13=0,F25,_xlfn.CONCAT(B13,IF(E13="", ," " ),E13 )) -> N n.e.s. | B13: N | C13: mass | D13: kg | E13: n.e.s.
A14: =IF(B14=0,F26,_xlfn.CONCAT(B14,IF(E14="", ," " ),E14 )) -> Na n.e.s. | B14: Na | C14: mass | D14: kg | E14: n.e.s.
A15: =IF(B15=0,F27,_xlfn.CONCAT(B15,IF(E15="", ," " ),E15 )) -> O n.e.s. | B15: O | C15: mass | D15: kg | E15: n.e.s.
A16: =IF(B16=0,F28,_xlfn.CONCAT(B16,IF(E16="", ," " ),E16 )) -> P n.e.s. | B16: P | C16: mass | D16: kg | E16: n.e.s.
A17: =IF(B17=0,F29,_xlfn.CONCAT(B17,IF(E17="", ," " ),E17 )) -> S n.e.s. | B17: S | C17: mass | D17: kg | E17: n.e.s.
A18: =IF(B18=0,F30,_xlfn.CONCAT(B18,IF(E18="", ," " ),E18 )) -> Ag n.e.s. | B18: Ag | C18: mass | D18: kg | E18: n.e.s.
A19: =IF(B19=0,#REF!,_xlfn.CONCAT(B19,IF(E19="", ," " ),E19 )) -> Al n.e.s. | B19: Al | C19: mass | D19: kg | E19: n.e.s.
A20: =IF(B20=0,F31,_xlfn.CONCAT(B20,IF(E20="", ," " ),E20 )) -> Ar n.e.s. | B20: Ar | C20: mass | D20: kg | E20: n.e.s.
A21: =IF(B21=0,F32,_xlfn.CONCAT(B21,IF(E21="", ," " ),E21 )) -> As n.e.s. | B21: As | C21: mass | D21: kg | E21: n.e.s.
A22: =IF(B22=0,F33,_xlfn.CONCAT(B22,IF(E22="", ," " ),E22 )) -> Cd n.e.s. | B22: Cd | C22: mass | D22: kg | E22: n.e.s.
A23: =IF(B23=0,F34,_xlfn.CONCAT(B23,IF(E23="", ," " ),E23 )) -> Co n.e.s. | B23: Co | C23: mass | D23: kg | E23: n.e.s.
A24: =IF(B24=0,F35,_xlfn.CONCAT(B24,IF(E24="", ," " ),E24 )) -> Cr n.e.s. | B24: Cr | C24: mass | D24: kg | E24: n.e.s.
A25: =IF(B25=0,F36,_xlfn.CONCAT(B25,IF(E25="", ," " ),E25 )) -> Cu n.e.s. | B25: Cu | C25: mass | D25: kg | E25: n.e.s.
A26: Fe n.e.s. | B26: Fe | C26: mass | D26: kg | E26: n.e.s.
A27: =IF(B27=0,F38,_xlfn.CONCAT(B27,IF(E27="", ," " ),E27 )) -> Hg n.e.s. | B27: Hg | C27: mass | D27: kg | E27: n.e.s.
A28: =IF(B28=0,#REF!,_xlfn.CONCAT(B28,IF(E28="", ," " ),E28 )) -> Mg n.e.s. | B28: Mg | C28: mass | D28: kg | E28: n.e.s.
A29: =IF(B29=0,F39,_xlfn.CONCAT(B29,IF(E29="", ," " ),E29 )) -> Mn n.e.s. | B29: Mn | C29: mass | D29: kg | E29: n.e.s.
A30: =IF(B30=0,F40,_xlfn.CONCAT(B30,IF(E30="", ," " ),E30 )) -> Mo n.e.s. | B30: Mo | C30: mass | D30: kg | E30: n.e.s.
A31: =IF(B31=0,F41,_xlfn.CONCAT(B31,IF(E31="", ," " ),E31 )) -> Ni n.e.s. | B31: Ni | C31: mass | D31: kg | E31: n.e.s.
A32: =IF(B32=0,F42,_xlfn.CONCAT(B32,IF(E32="", ," " ),E32 )) -> Pb n.e.s. | B32: Pb | C32: mass | D32: kg | E32: n.e.s.
A33: =IF(B33=0,F43,_xlfn.CONCAT(B33,IF(E33="", ," " ),E33 )) -> Zn n.e.s. | B33: Zn | C33: mass | D33: kg | E33: n.e.s.
A34: =IF(B34=0,F44,_xlfn.CONCAT(B34,IF(E34="", ," " ),E34 )) -> Inertes n.e.s. | B34: Inertes | C34: mass | D34: kg | E34: n.e.s.
A35: N2 | B35: N2 | C35: mass | D35: kg | E35: n.e.s.
A36: N2O | B36: Nitrous oxide | C36: mass | D36: kg
A37: NH3 | B37: Ammonia | C37: mass | D37: kg
A38: He n.e.s. | B38: He | C38: mass | D38: kg | E38: n.e.s.
A39: Li n.e.s. | B39: Li | C39: mass | D39: kg | E39: n.e.s.
A40: Be n.e.s. | B40: Be | C40: mass | D40: kg | E40: n.e.s.
A41: B n.e.s. | B41: Be | C41: mass | D41: kg | E41: n.e.s.
...

Sheet l_goods
A1: productId | B1: name | C1: reference_property | D1: unit | E1: Background Product Id | F1: Background Source Id | G1: ProxyComment
A3: A-01 | B3: Journaux | C3: Total mass [kg] | D3: kg
A4: A-02 | B4: Publications_et_circulaires_en_papier_journal | C4: Total mass [kg] | D4: kg
A5: A-03 | B5: Revues_et_magazines | C5: Total mass [kg] | D5: kg
A6: A-04 | B6: Catalogues_et_documents_reliés | C6: Total mass [kg] | D6: kg
A7: A-05 | B7: Bottins | C7: Total mass [kg] | D7: kg
A8: A-06 | B8: Papier_a_usage_general_/_Papier_de_bureau | C8: Total mass [kg] | D8: kg
A9: A-07 | B9: Autres_imprimes | C9: Total mass [kg] | D9: kg
A10: A-08 | B10: Livres | C10: Total mass [kg] | D10: kg
A11: A-09 | B11: Autres_imprimes_non_vises_par_EEQ | C11: Total mass [kg] | D11: kg
A12: B-01 | B12: Carton_ondule | C12: Total mass [kg] | D12: kg
A13: B-02 | B13: Sacs_d'emplettes_de_papier_kraft | C13: Total mass [kg] | D13: kg
A14: B-03 | B14: Emballages_de_papier_kraft | C14: Total mass [kg] | D14: kg
... A146: gisement_coll_orga | B146: Gisement catégorisé issu de la collecte de matiere organique | C146: Total mass [kg] | D146: kg
A147: electricity | B147: electricity | C147: Energy | D147: kWh | E147: d69294d7-8d64-4915-a896-9996a014c410 | F147: bc5a9265-2d59-4dd1-b532-b843edb5f4b0
A148: diesel | B148: diesel | C148: Volume | D148: L | E148: fecdf330-8660-4362-adde-ab5ea197ab1d | F148: 90784a59-3cf7-4ad2-b4cb-528ae6a58bae
A149: composting_facility_open | B149: Composting_facility, open | C149: Unit | D149: u | E149: bfdc2268-b9c4-462a-8971-4503ffdfbaf3 | F149: cb4febb0-8dbf-44ba-bace-b4a0fbf98f38
A151: compost_1_subst | B151: Substances et elements degradés, retrouvés dans le compost_1 | C151: Total mass [kg] | D151: kg
A152: compost_1_rem | B152: Goods remaining not degraded from composting, retrouvés dans le compost_1 | C152: Total mass [kg] | D152: kg
A154: oxygen_from_airtank | B154: Oxygen_from_airtank | C154: Total mass [kg] | D154: kg
A157: fertiliser_N | B157: calcium ammonium nitrate production | C157: Total mass [kg] | D157: kg | E157: f5707bdf-f7e2-479b-b3ea-99c04de8a927 | F157: 72881136-1c43-45fb-bf07-3cc6d0e24020 | G157: Produit : N
A159: fertiliser_P2O5 | B159: ammonium nitrate phosphate production | C159: Total mass [kg] | D159: kg | E159: 5321a299-0c03-4bfc-9dda-d020456f6b2e | F159: 8342cd50-4d9f-438b-b7c9-cc882d65d01a | G159: Produit : P2O5
A161: overs_end | B161: Overs_from_postscreen | C161: Total mass [kg] | D161: kg
A162: unders_end | B162: Unders_from_postscreen | C162: Total mass [kg] | D162: kg

Sheet l_act
A1: activityId | B1: name | C1: geography
A3: aggr_1 | B3: Aggrégation Recyc-Qc vers T2_SWOLF | C3: GLO | D3: =IF(B3&" "&C3=" ","",B3&" "&C3) -> Aggrégation Recyc-Qc vers T2_SWOLF GLO
A4: aggr_2 | B4: Aggrégation T2_SWOLF vers T25_SWOLF | C4: GLO | D4: =IF(B4&" "&C4=" ","",B4&" "&C4) -> Aggrégation T2_SWOLF vers T25_SWOLF GLO
A5: pre_screen_1 | B5: Pre_Screening_1 | C5: QC | D5: =IF(B5&" "&C5=" ","",B5&" "&C5) -> Pre_Screening_1 QC
A6: pre_screen_2 | B6: Pre_Screening_2 | C6: QC | D6: =IF(B6&" "&C6=" ","",B6&" "&C6) -> Pre_Screening_2 QC
A7: act_composting | B7: Active_Composting | C7: QC | D7: =IF(B7&" "&C7=" ","",B7&" "&C7) -> Active_Composting QC
A8: post_screen | B8: Post_Screening | C8: QC | D8: =IF(B8&" "&C8=" ","",B8&" "&C8) -> Post_Screening QC
A9: vacuum | B9: Vacuum | C9: QC | D9: =IF(#REF!&" "&C9=" ","",#REF!&" "&C9) -> #REF!
A10: mixing | B10: Mixing_before_activecomposting | C10: QC | D10: =IF(B10&" "&C10=" ","",B10&" "&C10) -> Mixing_before_activecomposting QC
A11: substitution_npk | B11: Substitution_of_fertilizers | C11: GLO | D11: =IF(B9&" "&C11=" ","",B9&" "&C11) -> Vacuum GLO
D12: =IF(B12&" "&C12=" ","",B12&" "&C12)
A13: compost_overall | B13: Compost | C13: QC | D13: =IF(B13&" "&C13=" ","",B13&" "&C13) -> Compost QC
D14: =IF(B14&" "&C14=" ","",B14&" "&C14)
D15: =IF(B15&" "&C15=" ","",B15&" "&C15)
D16: =IF(B16&" "&C16=" ","",B16&" "&C16)
D18: =IF(B18&" "&C18=" ","",B18&" "&C18)
D19: =IF(B19&" "&C19=" ","",B19&" "&C19)
D20: =IF(B20&" "&C20=" ","",B20&" "&C20)
D21: =IF(B21&" "&C21=" ","",B21&" "&C21)
D22: =IF(B22&" "&C22=" ","",B22&" "&C22)
D23: =IF(B23&" "&C23=" ","",B23&" "&C23)
D24: =IF(B24&" "&C24=" ","",B24&" "&C24)
D25: =IF(B25&" "&C25=" ","",B25&" "&C25)
D26: =IF(B26&" "&C26=" ","",B26&" "&C26)
... D202: =IF(B202&" "&C202=" ","",B202&" "&C202)

Sheet l_fp
A1: emissionId | B1: name | C1: reference_property | D1: comp | E1: subcomp | F1: unit
M2: Background Product Id | N2: Background Source Id | O2: ProxyComment
A4: 73ed05cc-9727-4abf-9516-4b5c0fe54a16 | B4: Carbon dioxide, non-fossil | C4: Total mass [kg] | D4: air | E4: urban air close to ground | F4: kg
A5: b53d3744-3629-4219-be20-980865e54031 | B5: Methane | C5: Total mass [kg] | D5: air | E5: urban air close to ground | F5: kg
A6: 9990b51b-7023-4700-bca0-1a32ef921f74 | B6: Ammonia | C6: Total mass [kg] | D6: air | E6: urban air close to ground | F6: kg
A7: d068f3e2-b033-417b-a359-ca4f25da9731 | B7: Nitrogen oxides | C7: Total mass [kg] | D7: air | E7: urban air close to ground | F7: kg
A8: e3f5fd63-7dcb-41f1-9b8a-a48a8d68bc65 | B8: Nitrogen | C8: Total mass [kg] | D8: natural resource | E8: in air | F8: kg
A9: af01e564-f816-4906-bd4f-b7c932f926b9 | B9: Oxygen | C9: Total mass [kg] | D9: natural resource | E9: in air | F9: kg

Sheet lay_goods
B1: productId | C1: ID of products inside product | E1: value
B2: collecte_orga | C2: F-04 | E2: 20568456
B3: collecte_orga | C3: F-04 | E3: 7548863
B4: collecte_orga | C4: F-01 | E4: 8273071.7
B5: collecte_orga | C5: F-02 | E5: 8273071.7
B6: collecte_orga | C6: F-03 | E6: 266838.77
B7: collecte_orga | C7: A-01 | E7: 254834
B8: collecte_orga | C8: A-06 | E8: 254834
B9: collecte_orga | C9: F-05 | E9: 1722150.1
B10: collecte_orga | C10: H-05 | E10: 15095.111
B11: collecte_orga | C11: C-06 | E11: 24009.547
B12: collecte_orga | C12: D-07 | E12: 23652.969
B13: collecte_orga | C13: E-18 | E13: 24247.265
... B21: collecte_orga | C21: G-04 | E21: 8438.9991

Sheet lay_trans
A1: id good | B1: {=IF(TRANSPOSE(l_goods!A3:A197)=0,"",TRANSPOSE(l_goods!A3:A197))} -> A-01 | C1: A-02 | D1: A-03 | E1: A-04 | F1: A-05 | G1: A-06 | H1: A-07 | I1: A-08 | J1: A-09 | K1: B-01 | L1: B-02 | M1: B-03 | N1: B-04 | O1: B-05 | P1: B-06 | Q1: B-07 | R1: B-08 | S1: B-09 | T1: B-10 | U1: B-11 | V1: B-12 | W1: C-01 | X1: C-02 | Y1: C-03 | Z1: C-04 | AA1: C-05 | AB1: C-06 | AC1: D-01 | AD1: D-02 | AE1: D-03 | AF1: D-04 | AG1: D-05 | AH1: D-06 | AI1: D-07 | AJ1: E-01 | AK1: E-02 | AL1: E-03 | AM1: E-04 | AN1: E-05 | AO1: E-06 | AP1: E-07 | AQ1: E-08 | AR1: E-09 | AS1: E-10 | AT1: E-11 | AU1: E-12 | AV1: E-13 | AW1: E-14 | AX1: E-15 | AY1: E-16 | AZ1: E-17 | BA1: E-18 | BB1: E-19 | BC1: E-20 | BD1: E-21 | BE1: E-22 | BF1: E-23 | BG1: E-24 | BH1: E-25 | BI1: E-26 | BJ1: E-27 | BK1: F-01 | BL1: F-02 | BM1: F-03 | BN1: F-04 | BO1: F-05 | BP1: G-01 | BQ1: G-02 | BR1: H-01 | BS1: H-02 | BT1: H-03 | BU1: H-04 | BV1: H-05 | BW1: H-06 | BX1: G-03 | BY1: G-04 | BZ1: H-07 | CA1: H-08 | CB1: H-09 | CC1: H-10 | CD1: H-11 | CF1: T2-01 | CG1: T2-02 | CH1: T2-03 | CI1: T2-04 | CJ1: T2-05 | CK1: T2-06 | CL1: T2-07 | CM1: T2-08 | CN1: T2-09 | CO1: T2-10 | CP1: T2-11 | CQ1: T2-12 | CR1: T2-13 | CS1: T2-14 | CT1: T2-15 | CU1: T2-16 | CV1: T2-17 | CW1: T2-18 | CX1: T2-19 | CY1: T2-20 | CZ1: T2-21 | DA1: T2-22 | DB1: T2-23 | DC1: T2-24 | DD1: T2-25 | DE1: T2-26 | DF1: T2-27 | DG1: T2-28 | DI1: T25-01 | DJ1: T25-02 | DK1: T25-03 | DL1: T25-04 | DM1: T25-05 | DN1: T25-06 | DO1: T25-07 | DP1: T25-08 | DQ1: T25-09 | DR1: T25-10 | DS1: T25-11 | DT1: T25-12 | DU1: T25-13 | DW1: overs_1 | DX1: unders_1 | DZ1: overs_2 | EA1: unders_2 | EB1: amendment_carbon | EC1: mixed | ED1: compost_1 | EE1: off_gas_1 | EF1: off_gas | EG1: collecte_orga | EI1: overs_postscreen | EJ1: unders_postscreen | EL1: vac_out | EM1: compost_final | EN1: compost_mature | EO1: gisement_coll_orga | EP1: electricity | EQ1: diesel | ER1: composting_facility_open | ET1: compost_1_subst | EU1: compost_1_rem | EW1: oxygen_from_airtank | EZ1: fertiliser_N | FB1: fertiliser_P2O5 | FD1: overs_end | FE1: unders_end | GO1: #N/A
A4: =l_trans!$A$3 -> CO2
A5: =l_trans!$A4 -> CH4
A7: =l_trans!$A5 -> C n.e.s.
A8: =l_trans!$A6 -> C_bio | B8: 0.446 | C8: 0.344 | D8: 0.34 | E8: 0.34 | F8: 0.404 | G8: 0.373 | H8: 0.381 | I8: 0.404 | J8: 0.407 | K8: 0.407 | L8: 0.409 | M8: 0.407 | N8: 0.407 | O8: 0.409 | P8: 0.409 | Q8: 0.506 | R8: 0.46 | S8: 0.381 | T8: 0.506 | U8: 0.506 | V8: 0.513 | W8: 0 | X8: 0 | Y8: 0 | Z8: 0 | AA8: 0 | AB8: 0 | AC8: 0 | AD8: 0 | AE8: 0.137 | AF8: 0.137 | AG8: 0 | AH8: 0 | AI8: 0 | AJ8: 0.00355 | AK8: 0.00355 | AL8: 0.00355 | AM8: 0.00355 | AN8: 0.00355 | AO8: 0.00355 | AP8: 0.004 | AQ8: 0.004 | AR8: 0.00355 | AS8: 0.00355 | AT8: 0.004 | AU8: 0.00355 | AV8: 0.004 | AW8: 0.004 | AX8: 0.004 | AY8: 0.004 | AZ8: 0.004 | BA8: 0.004 | BB8: 0.004 | BC8: 0.0041 | BD8: 0.0041 | BE8: 0.0041 | BF8: 0.0041 | BG8: 0.0041 | BH8: 0.004 | BI8: 0.0041 | BJ8: 0.1485 | BK8: 0.421 | BL8: 0.421 | BM8: 0.421 | BN8: 0.475 | BO8: 0.447 | BP8: 0.498 | BQ8: 0.435 | BR8: 0.0065 | BS8: 0.0065 | BT8: 0.513 | BU8: 0.0065 | BV8: 0.0435 | BW8: 0.391 | BX8: 0.0065 | BY8: 0.0065 | BZ8: 0.0435 | CA8: 0.523 | CB8: 0 | CC8: 0 | CD8: 0
A9: =l_trans!$A7 -> C_fossil | B9: 0.00224 | C9: 0.00173 | D9: 0.00171 | E9: 0.00171 | F9: 0.00203 | G9: 0.00188 | H9: 0.00192 | I9: 0.00203 | J9: 0.00205 | K9: 0.00205 | L9: 0.00206 | M9: 0.00205 | N9: 0.00205 | O9: 0.00206 | P9: 0.00206 | Q9: 0.0103 | R9: 0.0628 | S9: 0.00192 | T9: 0.0103 | U9: 0.0103 | V9: 0.00782 | W9: 0 | X9: 0 | Y9: 0 | Z9: 0 | AA9: 0 | AB9: 0 | AC9: 0 | AD9: 0 | AE9: 0.0152 | AF9: 0.0152 | AG9: 0 | AH9: 0 | AI9: 0 | AJ9: 0.706 | AK9: 0.706 | AL9: 0.706 | AM9: 0.706 | AN9: 0.706 | AO9: 0.706 | AP9: 0.795 | AQ9: 0.795 | AR9: 0.706 | AS9: 0.706 | AT9: 0.795 | AU9: 0.706 | AV9: 0.795 | AW9: 0.795 | AX9: 0.795 | AY9: 0.795 | AZ9: 0.795 | BA9: 0.795 | BB9: 0.795 | BC9: 0.816 | BD9: 0.816 | BE9: 0.816 | BF9: 0.816 | BG9: 0.816 | BH9: 0.795 | BI9: 0.816 | BJ9: 0.4455 | BK9: 0.0086 | BL9: 0.0086 | BM9: 0.0086 | BN9: 0.00239 | BO9: 0.00452 | BP9: 0.0553 | BQ9: 0.00439 | BR9: 0.0065 | BS9: 0.0065 | BT9: 0.00782 | BU9: 0.0065 | BV9: 0.0435 | BW9: 0.13 | BX9: 0.0065 | BY9: 0.0065 | BZ9: 0.0435 | CA9: 0.131 | CB9: 0 | CC9: 0 | CD9: 0
A10: =l_trans!$A8 -> Ca n.e.s. | B10: 0.0111 | C10: 0.036 | D10: 0.101 | E10: 0.101 | F10: 0.0406 | G10: 0.0777 | H10: 0.0439 | I10: 0.0406 | J10: 0.0309 | K10: 0.0309 | L10: 0.0262 | M10: 0.0309 | N10: 0.0309 | O10: 0.0262 | P10: 0.0262 | Q10: 0.00782 | R10: 0.000727 | S10: 0.0439 | T10: 0.00782 | U10: 0.00782 | V10: 0.00964 | W10: 0.069 | X10: 0.069 | Y10: 0.0668 | Z10: 0.0668 | AA10: 0.0677 | AB10: 0.0679 | AC10: 3.56e-05 | AD10: 3.56e-05 | AE10: 0.00133 | AF10: 0.00133 | AG10: 0.0015 | AH10: 0.000244 | AI10: 0.0015 | AJ10: 0.0109 | AK10: 0.0109 | AL10: 0.0109 | AM10: 0.0109 | AN10: 0.0109 | AO10: 0.0109 | AP10: 0.00416 | AQ10: 0.00416 | AR10: 0.0109 | AS10: 0.0109 | AT10: 0.00416 | AU10: 0.0109 | AV10: 0.00416 | AW10: 0.00416 | AX10: 0.00416 | AY10: 0.00416 | AZ10: 0.00416 | BA10: 0.00416 | BB10: 0.00416 | BC10: 0.0011 | BD10: 0.0011 | BE10: 0.0011 | BF10: 0.0011 | BG10: 0.0011 | BH10: 0.00416 | BI10: 0.0011 | BJ10: 0.00761 | BK10: 0.0211 | BL10: 0.0211 | BM10: 0.0211 | BN10: 0.00555 | BO10: 0.00393 | BP10: 0.00962 | BQ10: 0.0271 | BR10: 0.0459 | BS10: 0.0459 | BT10: 0.00964 | BU10: 0.0459 | BV10: 0.000876 | BW10: 0.0044 | BX10: 0.0459 | BY10: 0.0459 | BZ10: 0.000876 | CA10: 0.0228 | CB10: 0.0501 | CC10: 0.0501 | CD10: 0.0501
A11: =l_trans!$A9 -> Cl n.e.s. | B11: 0.0003 | C11: 0.0003 | D11: 0.0003 | E11: 0.0003 | F11: 0.0003 | G11: 0.0007 | H11: 0.0006 | I11: 0.0003 | J11: 0.0002 | K11: 0.0002 | L11: 0.0003 | M11: 0.0002 | N11: 0.0002 | O11: 0.0003 | P11: 0.0003 | Q11: 0.0011 | R11: 0.0003 | S11: 0.0006 | T11: 0.0011 | U11: 0.0011 | V11: 0.0014 | W11: 0 | X11: 0 | Y11: 0 | Z11: 0 | AA11: 0 | AB11: 0 | AC11: 0 | AD11: 0 | AE11: 0.0024 | AF11: 0.0024 | AG11: 0 | AH11: 0 | AI11: 0 | AJ11: 0.0468 | AK11: 0.0468 | AL11: 0.0468 | AM11: 0.0468 | AN11: 0.0468 | AO11: 0.0468 | AP11: 0.001 | AQ11: 0.001 | AR11: 0.0468 | AS11: 0.0468 | AT11: 0.001 | AU11: 0.0468 | AV11: 0.001 | AW11: 0.001 | AX11: 0.001 | AY11: 0.001 | AZ11: 0.001 | BA11: 0.001 | BB11: 0.001 | BC11: 0.0007 | BD11: 0.0007 | BE11: 0.0007 | BF11: 0.0007 | BG11: 0.0007 | BH11: 0.001 | BI11: 0.0007 | BJ11: 0.0276 | BK11: 0.0028 | BL11: 0.0028 | BM11: 0.0028 | BN11: 0.0056 | BO11: 0.0026 | BP11: 0.0014 | BQ11: 0.0013 | BR11: 0.0002 | BS11: 0.0002 | BT11: 0.0014 | BU11: 0.0002 | BV11: 0.0158 | BW11: 0.0035 | BX11: 0.0002 | BY11: 0.0002 | BZ11: 0.0158 | CA11: 0.0938 | CB11: 0.0107 | CC11: 0.0107 | CD11: 0.0107
A12: =l_trans!$A10 -> F n.e.s. | B12: 0.0001 | C12: 0.0007 | D12: 0.0001 | E12: 0.0001 | F12: 0.00016 | G12: 0.0001 | H12: 0.0001 | I12: 0.00016 | J12: 0.0002 | K12: 0.0002 | L12: 0.0004 | M12: 0.0002 | N12: 0.0002 | O12: 0.0004 | P12: 0.0004 | Q12: 0.0001 | R12: 0.0001 | S12: 0.0001 | T12: 0.0001 | U12: 0.0001 | V12: 0.0001 | W12: 0 | X12: 0 | Y12: 0 | Z12: 0 | AA12: 0 | AB12: 0 | AC12: 0 | AD12: 0 | AE12: 0.0001 | AF12: 0.0001 | AG12: 0 | AH12: 0 | AI12: 0 | AJ12: 0.0001 | AK12: 0.0001 | AL12: 0.0001 | AM12: 0.0001 | AN12: 0.0001 | AO12: 0.0001 | AP12: 0.0001 | AQ12: 0.0001 | AR12: 0.0001 | AS12: 0.0001 | AT12: 0.0001 | AU12: 0.0001 | AV12: 0.0001 | AW12: 0.0001 | AX12: 0.0001 | AY12: 0.0001 | AZ12: 0.0001 | BA12: 0.0001 | BB12: 0.0001 | BC12: 0.0001 | BD12: 0.0001 | BE12: 0.0001 | BF12: 0.0001 | BG12: 0.0001 | BH12: 0.0001 | BI12: 0.0001 | BJ12: 0.0001 | BK12: 0.0001 | BL12: 0.0001 | BM12: 0.0001 | BN12: 0.0001 | BO12: 0.0001 | BP12: 0.0001 | BQ12: 0.0001 | BR12: 0.0003 | BS12: 0.0003 | BT12: 0.0001 | BU12: 0.0003 | BV12: 0.0001 | BW12: 0.0001 | BX12: 0.0003 | BY12: 0.0003 | BZ12: 0.0001 | CA12: 0.0001 | CB12: 0 | CC12: 0 | CD12: 0
A13: =l_trans!$A11 -> H n.e.s. | B13: 0.057 | C13: 0.048 | D13: 0.042 | E13: 0.042 | F13: 0.0516 | G13: 0.05 | H13: 0.05 | I13: 0.0516 | J13: 0.054 | K13: 0.054 | L13: 0.056 | M13: 0.054 | N13: 0.054 | O13: 0.056 | P13: 0.056 | Q13: 0.077 | R13: 0.073 | S13: 0.05 | T13: 0.077 | U13: 0.077 | V13: 0.064 | W13: 0 | X13: 0 | Y13: 0 | Z13: 0 | AA13: 0 | AB13: 0 | AC13: 0 | AD13: 0 | AE13: 0.027 | AF13: 0.027 | AG13: 0 | AH13: 0 | AI13: 0 | AJ13: 0.097 | AK13: 0.097 | AL13: 0.097 | AM13: 0.097 | AN13: 0.097 | AO13: 0.097 | AP13: 0.105 | AQ13: 0.105 | AR13: 0.097 | AS13: 0.097 | AT13: 0.105 | AU13: 0.097 | AV13: 0.105 | AW13: 0.105 | AX13: 0.105 | AY13: 0.105 | AZ13: 0.105 | BA13: 0.105 | BB13: 0.105 | BC13: 0.132 | BD13: 0.132 | BE13: 0.132 | BF13: 0.132 | BG13: 0.132 | BH13: 0.105 | BI13: 0.132 | BJ13: 0.069 | BK13: 0.052 | BL13: 0.052 | BM13: 0.052 | BN13: 0.066 | BO13: 0.063 | BP13: 0.08 | BQ13: 0.064 | BR13: 0.001 | BS13: 0.001 | BT13: 0.064 | BU13: 0.001 | BV13: 0.011 | BW13: 0.06 | BX13: 0.001 | BY13: 0.001 | BZ13: 0.011 | CA13: 0.084 | CB13: 0 | CC13: 0 | CD13: 0
A14: =l_trans!$A12 -> K n.e.s. | B14: 0.000672 | C14: 0.000899 | D14: 0.000686 | E14: 0.000686 | F14: 0.000699 | G14: 0.000118 | H14: 0.00073 | I14: 0.000699 | J14: 0.000397 | K14: 0.000397 | L14: 0.000374 | M14: 0.000397 | N14: 0.000397 | O14: 0.000374 | P14: 0.000374 | Q14: 0.000571 | R14: 0.000472 | S14: 0.00073 | T14: 0.000571 | U14: 0.000571 | V14: 0.00212 | W14: 0.00775 | X14: 0.00775 | Y14: 0.00701 | Z14: 0.00701 | AA14: 0.00365 | AB14: 0.00443 | AC14: 0.000162 | AD14: 0.000162 | AE14: 0.00119 | AF14: 0.00119 | AG14: 0.0002 | AH14: 0.000532 | AI14: 0.0002 | AJ14: 0.00121 | AK14: 0.00121 | AL14: 0.00121 | AM14: 0.00121 | AN14: 0.00121 | AO14: 0.00121 | AP14: 0.00019 | AQ14: 0.00019 | AR14: 0.00121 | AS14: 0.00121 | AT14: 0.00019 | AU14: 0.00121 | AV14: 0.00019 | AW14: 0.00019 | AX14: 0.00019 | AY14: 0.00019 | AZ14: 0.00019 | BA14: 0.00019 | BB14: 0.00019 | BC14: 0.000673 | BD14: 0.000673 | BE14: 0.000673 | BF14: 0.000673 | BG14: 0.000673 | BH14: 0.00019 | BI14: 0.000673 | BJ14: 0.000278 | BK14: 0.0127 | BL14: 0.0127 | BM14: 0.0127 | BN14: 0.0127 | BO14: 0.00151 | BP14: 0.00141 | BQ14: 0.00739 | BR14: 0.0104 | BS14: 0.0104 | BT14: 0.00212 | BU14: 0.0104 | BV14: 0.0397 | BW14: 0.000706 | BX14: 0.0104 | BY14: 0.0104 | BZ14: 0.0397 | CA14: 0.000559 | CB14: 0.017 | CC14: 0.017 | CD14: 0.017
A15: =l_trans!$A13 -> N n.e.s. | B15: 0.001 | C15: 0.003 | D15: 0.001 | E15: 0.001 | F15: 0.0012 | G15: 0.001 | H15: 0.002 | I15: 0.0012 | J15: 0.001 | K15: 0.001 | L15: 0.002 | M15: 0.001 | N15: 0.001 | O15: 0.002 | P15: 0.002 | Q15: 0.002 | R15: 0.004 | S15: 0.002 | T15: 0.002 | U15: 0.002 | V15: 0.008 | W15: 0 | X15: 0 | Y15: 0 | Z15: 0 | AA15: 0 | AB15: 0 | AC15: 0 | AD15: 0 | AE15: 0.004 | AF15: 0.004 | AG15: 0 | AH15: 0 | AI15: 0 | AJ15: 0.005 | AK15: 0.005 | AL15: 0.005 | AM15: 0.005 | AN15: 0.005 | AO15: 0.005 | AP15: 0.055 | AQ15: 0.055 | AR15: 0.005 | AS15: 0.005 | AT15: 0.055 | AU15: 0.005 | AV15: 0.055 | AW15: 0.055 | AX15: 0.055 | AY15: 0.055 | AZ15: 0.055 | BA15: 0.055 | BB15: 0.055 | BC15: 0.002 | BD15: 0.002 | BE15: 0.002 | BF15: 0.002 | BG15: 0.002 | BH15: 0.055 | BI15: 0.002 | BJ15: 0.022 | BK15: 0.015 | BL15: 0.015 | BM15: 0.015 | BN15: 0.019 | BO15: 0.008 | BP15: 0.009 | BQ15: 0.033 | BR15: 0 | BS15: 0 | BT15: 0.008 | BU15: 0 | BV15: 0.001 | BW15: 0.032 | BX15: 0 | BY15: 0 | BZ15: 0.001 | CA15: 0.006 | CB15: 0.00103 | CC15: 0.00103 | CD15: 0.00103
A16: =l_trans!$A14 -> Na n.e.s. | B16: 0.000246 | C16: 0.00128 | D16: 0.000898 | E16: 0.000898 | F16: 0.000545 | G16: 0.000774 | H16: 0.000977 | I16: 0.000545 | J16: 0.000416 | K16: 0.000416 | L16: 0.000476 | M16: 0.000416 | N16: 0.000416 | O16: 0.000476 | P16: 0.000476 | Q16: 0.00174 | R16: 0.0015 | S16: 0.000977 | T16: 0.00174 | U16: 0.00174 | V16: 0.000703 | W16: 0.0249 | X16: 0.0249 | Y16: 0.0261 | Z16: 0.0261 | AA16: 0.0224 | AB16: 0.023 | AC16: 0.000165 | AD16: 0.000165 | AE16: 0.00167 | AF16: 0.00167 | AG16: 0.00039 | AH16: 0.000539 | AI16: 0.00039 | AJ16: 0.00117 | AK16: 0.00117 | AL16: 0.00117 | AM16: 0.00117 | AN16: 0.00117 | AO16: 0.00117 | AP16: 0.000422 | AQ16: 0.000422 | AR16: 0.00117 | AS16: 0.00117 | AT16: 0.000422 | AU16: 0.00117 | AV16: 0.000422 | AW16: 0.000422 | AX16: 0.000422 | AY16: 0.000422 | AZ16: 0.000422 | BA16: 0.000422 | BB16: 0.000422 | BC16: 0.000554 | BD16: 0.000554 | BE16: 0.000554 | BF16: 0.000554 | BG16: 0.000554 | BH16: 0.000422 | BI16: 0.000554 | BJ16: 0.000575 | BK16: 0.000944 | BL16: 0.000944 | BM16: 0.000944 | BN16: 0.00312 | BO16: 0.00206 | BP16: 0.0219 | BQ16: 0.00241 | BR16: 0.0417 | BS16: 0.0417 | BT16: 0.000703 | BU16: 0.0417 | BV16: 0.00148 | BW16: 0.00359 | BX16: 0.0417 | BY16: 0.0417 | BZ16: 0.00148 | CA16: 0.000347 | CB16: 0.0118 | CC16: 0.0118 | CD16: 0.0118
A17: =l_trans!$A15 -> O n.e.s. | B17: 0.442 | C17: 0.329 | D17: 0.275 | E17: 0.275 | F17: 0.381 | G17: 0.367 | H17: 0.385 | I17: 0.381 | J17: 0.395 | K17: 0.395 | L17: 0.396 | M17: 0.395 | N17: 0.395 | O17: 0.396 | P17: 0.396 | Q17: 0.308 | R17: 0.388 | S17: 0.385 | T17: 0.308 | U17: 0.308 | V17: 0.305 | W17: 0 | X17: 0 | Y17: 0 | Z17: 0 | AA17: 0 | AB17: 0 | AC17: 0 | AD17: 0 | AE17: 0.0535 | AF17: 0.0535 | AG17: 0 | AH17: 0 | AI17: 0 | AJ17: 0.111 | AK17: 0.111 | AL17: 0.111 | AM17: 0.111 | AN17: 0.111 | AO17: 0.111 | AP17: 0.0173 | AQ17: 0.0173 | AR17: 0.111 | AS17: 0.111 | AT17: 0.0173 | AU17: 0.111 | AV17: 0.0173 | AW17: 0.0173 | AX17: 0.0173 | AY17: 0.0173 | AZ17: 0.0173 | BA17: 0.0173 | BB17: 0.0173 | BC17: 0.0011 | BD17: 0.0011 | BE17: 0.0011 | BF17: 0.0011 | BG17: 0.0011 | BH17: 0.0173 | BI17: 0.0011 | BJ17: 0.0356 | BK17: 0.259 | BL17: 0.259 | BM17: 0.259 | BN17: 0.395 | BO17: 0.448 | BP17: 0.273 | BQ17: 0.208 | BR17: 0.0074 | BS17: 0.0074 | BT17: 0.305 | BU17: 0.0074 | BV17: 0.027 | BW17: 0.348 | BX17: 0.0074 | BY17: 0.0074 | BZ17: 0.027 | CA17: 0.0659 | CB17: 0 | CC17: 0 | CD17: 0 | EW17: 1
A18: =l_trans!$A16 -> P n.e.s. | B18: 7.45e-05 | C18: 0.000155 | D18: 0.00018 | E18: 0.00018 | F18: 0.000114 | G18: 3.82e-05 | H18: 9.57e-05 | I18: 0.000114 | J18: 0.000125 | K18: 0.000125 | L18: 0.000129 | M18: 0.000125 | N18: 0.000125 | O18: 0.000129 | P18: 0.000129 | Q18: 0.000189 | R18: 0.00033 | S18: 9.57e-05 | T18: 0.000189 | U18: 0.000189 | V18: 0.000274 | W18: 9.55e-05 | X18: 9.55e-05 | Y18: 0.000122 | Z18: 0.000122 | AA18: 6.4e-05 | AB18: 7.16e-05 | AC18: 0.00011 | AD18: 0.00011 | AE18: 0.000551 | AF18: 0.000551 | AG18: 0.000252 | AH18: 0.000212 | AI18: 0.000252 | AJ18: 0.00561 | AK18: 0.00561 | AL18: 0.00561 | AM18: 0.00561 | AN18: 0.00561 | AO18: 0.00561 | AP18: 7.56e-05 | AQ18: 7.56e-05 | AR18: 0.00561 | AS18: 0.00561 | AT18: 7.56e-05 | AU18: 0.00561 | AV18: 7.56e-05 | AW18: 7.56e-05 | AX18: 7.56e-05 | AY18: 7.56e-05 | AZ18: 7.56e-05 | BA18: 7.56e-05 | BB18: 7.56e-05 | BC18: 0.000217 | BD18: 0.000217 | BE18: 0.000217 | BF18: 0.000217 | BG18: 0.000217 | BH18: 7.56e-05 | BI18: 0.000217 | BJ18: 0.000148 | BK18: 0.00198 | BL18: 0.00198 | BM18: 0.00198 | BN18: 0.00231 | BO18: 0.0011 | BP18: 0.000608 | BQ18: 0.0159 | BR18: 0.00013 | BS18: 0.00013 | BT18: 0.000274 | BU18: 0.00013 | BV18: 1e-05 | BW18: 0.0023 | BX18: 0.00013 | BY18: 0.00013 | BZ18: 1e-05 | CA18: 0.000313 | CB18: 0.000439 | CC18: 0.000439 | CD18: 0.000439
A19: =l_trans!$A17 -> S n.e.s. | B19: 0.000319 | C19: 0.000784 | D19: 0.000724 | E19: 0.000724 | F19: 0.000487 | G19: 0.000643 | H19: 0.00178 | I19: 0.000487 | J19: 0.000631 | K19: 0.000631 | L19: 0.001 | M19: 0.000631 | N19: 0.000631 | O19: 0.001 | P19: 0.001 | Q19: 0.000534 | R19: 0.000701 | S19: 0.00178 | T19: 0.000534 | U19: 0.000534 | V19: 0.000836 | W19: 0.000111 | X19: 0.000111 | Y19: 9.16e-05 | Z19: 9.16e-05 | AA19: 0.000832 | AB19: 0.000687 | AC19: 3e-05 | AD19: 3e-05 | AE19: 0.000297 | AF19: 0.000297 | AG19: 0.000321 | AH19: 9.9e-05 | AI19: 0.000321 | AJ19: 0.00052 | AK19: 0.00052 | AL19: 0.00052 | AM19: 0.00052 | AN19: 0.00052 | AO19: 0.00052 | AP19: 0.000988 | AQ19: 0.000988 | AR19: 0.00052 | AS19: 0.00052 | AT19: 0.000988 | AU19: 0.00052 | AV19: 0.000988 | AW19: 0.000988 | AX19: 0.000988 | AY19: 0.000988 | AZ19: 0.000988 | BA19: 0.000988 | BB19: 0.000988 | BC19: 0.000281 | BD19: 0.000281 | BE19: 0.000281 | BF19: 0.000281 | BG19: 0.000281 | BH19: 0.000988 | BI19: 0.000281 | BJ19: 0.000551 | BK19: 0.0019 | BL19: 0.0019 | BM19: 0.0019 | BN19: 0.00184 | BO19: 0.000883 | BP19: 0.000718 | BQ19: 0.00412 | BR19: 0.000537 | BS19: 0.000537 | BT19: 0.000836 | BU19: 0.000537 | BV19: 0.00165 | BW19: 0.00397 | BX19: 0.000537 | BY19: 0.000537 | BZ19: 0.00165 | CA19: 0.00605 | CB19: 0 | CC19: 0 | CD19: 0
A20: =l_trans!$A18 -> Ag n.e.s. | B20: 0 | C20: 0 | D20: 0 | E20: 0 | F20: 0 | G20: 0 | H20: 0 | I20: 0 | J20: 0 | K20: 0 | L20: 0 | M20: 0 | N20: 0 | O20: 0 | P20: 0 | Q20: 0 | R20: 0 | S20: 0 | T20: 0 | U20: 0 | V20: 0 | W20: 0 | X20: 0 | Y20: 0 | Z20: 0 | AA20: 0 | AB20: 0 | AC20: 0 | AD20: 0 | AE20: 0 | AF20: 0 | AG20: 0 | AH20: 0 | AI20: 0 | AJ20: 0 | AK20: 0 | AL20: 0 | AM20: 0 | AN20: 0 | AO20: 0 | AP20: 0 | AQ20: 0 | AR20: 0 | AS20: 0 | AT20: 0 | AU20: 0 | AV20: 0 | AW20: 0 | AX20: 0 | AY20: 0 | AZ20: 0 | BA20: 0 | BB20: 0 | BC20: 0 | BD20: 0 | BE20: 0 | BF20: 0 | BG20: 0 | BH20: 0 | BI20: 0 | BJ20: 0 | BK20: 0 | BL20: 0 | BM20: 0 | BN20: 0 | BO20: 0 | BP20: 0 | BQ20: 0 | BR20: 0 | BS20: 0 | BT20: 0 | BU20: 0 | BV20: 0 | BW20: 0 | BX20: 0 | BY20: 0 | BZ20: 0 | CA20: 0 | CB20: 0 | CC20: 0 | CD20: 0
A21: =l_trans!$A19 -> Al n.e.s. | B21: 0.00885 | C21: 0.0324 | D21: 0.0146 | E21: 0.0146 | F21: 0.0129 | G21: 0.00131 | H21: 0.0117 | I21: 0.0129 | J21: 0.0119 | K21: 0.0119 | L21: 0.0128 | M21: 0.0119 | N21: 0.0119 | O21: 0.0128 | P21: 0.0128 | Q21: 0.0558 | R21: 0.00143 | S21: 0.0117 | T21: 0.0558 | U21: 0.0558 | V21: 0.0044 | W21: 0.00762 | X21: 0.00762 | Y21: 0.00987 | Z21: 0.00987 | AA21: 0.00686 | AB21: 0.00712 | AC21: 0.628 | AD21: 0.628 | AE21: 0.6552 | AF21: 0.6552 | AG21: 0.0378 | AH21: 0.215 | AI21: 0.0378 | AJ21: 0.00565 | AK21: 0.00565 | AL21: 0.00565 | AM21: 0.00565 | AN21: 0.00565 | AO21: 0.00565 | AP21: 0.00143 | AQ21: 0.00143 | AR21: 0.00565 | AS21: 0.00565 | AT21: 0.00143 | AU21: 0.00565 | AV21: 0.00143 | AW21: 0.00143 | AX21: 0.00143 | AY21: 0.00143 | AZ21: 0.00143 | BA21: 0.00143 | BB21: 0.00143 | BC21: 0.000692 | BD21: 0.000692 | BE21: 0.000692 | BF21: 0.000692 | BG21: 0.000692 | BH21: 0.00143 | BI21: 0.000692 | BJ21: 0.0316 | BK21: 0.00236 | BL21: 0.00236 | BM21: 0.00236 | BN21: 0.00103 | BO21: 0.000681 | BP21: 0.000454 | BQ21: 0.00422 | BR21: 0.0112 | BS21: 0.0112 | BT21: 0.0044 | BU21: 0.0112 | BV21: 0.0013 | BW21: 0.000879 | BX21: 0.0112 | BY21: 0.0112 | BZ21: 0.0013 | CA21: 0.00154 | CB21: 0.0118 | CC21: 0.0118 | CD21: 0.0118
A22: =l_trans!$A20 -> Ar n.e.s. | B22: 0 | C22: 0 | D22: 0 | E22: 0 | F22: 0 | G22: 0 | H22: 0 | I22: 0 | J22: 0 | K22: 0 | L22: 0 | M22: 0 | N22: 0 | O22: 0 | P22: 0 | Q22: 0 | R22: 0 | S22: 0 | T22: 0 | U22: 0 | V22: 0 | W22: 0 | X22: 0 | Y22: 0 | Z22: 0 | AA22: 0 | AB22: 0 | AC22: 0 | AD22: 0 | AE22: 0 | AF22: 0 | AG22: 0 | AH22: 0 | AI22: 0 | AJ22: 0 | AK22: 0 | AL22: 0 | AM22: 0 | AN22: 0 | AO22: 0 | AP22: 0 | AQ22: 0 | AR22: 0 | AS22: 0 | AT22: 0 | AU22: 0 | AV22: 0 | AW22: 0 | AX22: 0 | AY22: 0 | AZ22: 0 | BA22: 0 | BB22: 0 | BC22: 0 | BD22: 0 | BE22: 0 | BF22: 0 | BG22: 0 | BH22: 0 | BI22: 0 | BJ22: 0 | BK22: 0 | BL22: 0 | BM22: 0 | BN22: 0 | BO22: 0 | BP22: 0 | BQ22: 0 | BR22: 0 | BS22: 0 | BT22: 0 | BU22: 0 | BV22: 0 | BW22: 0 | BX22: 0 | BY22: 0 | BZ22: 0 | CA22: 0 | CB22: 0 | CC22: 0 | CD22: 0
A23: =l_trans!$A21 -> As n.e.s. | B23: 4.83e-07 | C23: 6.7e-07 | D23: 6.06e-07 | E23: 6.06e-07 | F23: 5.39e-07 | G23: 2.13e-07 | H23: 6.7e-07 | I23: 5.39e-07 | J23: 3.07e-07 | K23: 3.07e-07 | L23: 2.94e-07 | M23: 3.07e-07 | N23: 3.07e-07 | O23: 2.94e-07 | P23: 2.94e-07 | Q23: 2e-07 | R23: 2e-07 | S23: 6.7e-07 | T23: 2e-07 | U23: 2e-07 | V23: 3.05e-07 | W23: 6.53e-06 | X23: 6.53e-06 | Y23: 4.07e-06 | Z23: 4.07e-06 | AA23: 3.12e-06 | AB23: 3.68e-06 | AC23: 9.13e-06 | AD23: 9.13e-06 | AE23: 2e-06 | AF23: 2e-06 | AG23: 4.92e-05 | AH23: 2.5e-05 | AI23: 4.92e-05 | AJ23: 2e-07 | AK23: 2e-07 | AL23: 2e-07 | AM23: 2e-07 | AN23: 2e-07 | AO23: 2e-07 | AP23: 4.78e-07 | AQ23: 4.78e-07 | AR23: 2e-07 | AS23: 2e-07 | AT23: 4.78e-07 | AU23: 2e-07 | AV23: 4.78e-07 | AW23: 4.78e-07 | AX23: 4.78e-07 | AY23: 4.78e-07 | AZ23: 4.78e-07 | BA23: 4.78e-07 | BB23: 4.78e-07 | BC23: 2e-07 | BD23: 2e-07 | BE23: 2e-07 | BF23: 2e-07 | BG23: 2e-07 | BH23: 4.78e-07 | BI23: 2e-07 | BJ23: 3.22e-06 | BK23: 9.41e-07 | BL23: 9.41e-07 | BM23: 9.41e-07 | BN23: 2.62e-07 | BO23: 2e-07 | BP23: 2e-07 | BQ23: 6.29e-07 | BR23: 6.38e-05 | BS23: 6.38e-05 | BT23: 3.05e-07 | BU23: 6.38e-05 | BV23: 8.3e-05 | BW23: 2e-07 | BX23: 6.38e-05 | BY23: 6.38e-05 | BZ23: 8.3e-05 | CA23: 2.46e-07 | CB23: 2.85e-06 | CC23: 2.85e-06 | CD23: 2.85e-06
A24: =l_trans!$A22 -> Cd n.e.s. | B24: 7.37e-08 | C24: 4.1e-08 | D24: 4.76e-08 | E24: 4.76e-08 | F24: 6.26e-08 | G24: 5.34e-08 | H24: 5.42e-08 | I24: 6.26e-08 | J24: 4.65e-08 | K24: 4.65e-08 | L24: 9.81e-08 | M24: 4.65e-08 | N24: 4.65e-08 | O24: 9.81e-08 | P24: 9.81e-08 | Q24: 2.74e-08 | R24: 1e-08 | S24: 5.42e-08 | T24: 2.74e-08 | U24: 2.74e-08 | V24: 3.41e-07 | W24: 1.6e-07 | X24: 1.6e-07 | Y24: 1.2e-07 | Z24: 1.2e-07 | AA24: 1.21e-07 | AB24: 1.27e-07 | AC24: 4.71e-07 | AD24: 4.71e-07 | AE24: 5.48e-07 | AF24: 5.48e-07 | AG24: 1.41e-06 | AH24: 1.49e-06 | AI24: 1.41e-06 | AJ24: 3.44e-08 | AK24: 3.44e-08 | AL24: 3.44e-08 | AM24: 3.44e-08 | AN24: 3.44e-08 | AO24: 3.44e-08 | AP24: 3.51e-07 | AQ24: 3.51e-07 | AR24: 3.44e-08 | AS24: 3.44e-08 | AT24: 3.51e-07 | AU24: 3.44e-08 | AV24: 3.51e-07 | AW24: 3.51e-07 | AX24: 3.51e-07 | AY24: 3.51e-07 | AZ24: 3.51e-07 | BA24: 3.51e-07 | BB24: 3.51e-07 | BC24: 3.43e-08 | BD24: 3.43e-08 | BE24: 3.43e-08 | BF24: 3.43e-08 | BG24: 3.43e-08 | BH24: 3.51e-07 | BI24: 3.43e-08 | BJ24: 2.78e-06 | BK24: 3.57e-07 | BL24: 3.57e-07 | BM24: 3.57e-07 | BN24: 9.46e-08 | BO24: 2.24e-08 | BP24: 2.02e-08 | BQ24: 2.61e-07 | BR24: 7.91e-06 | BS24: 7.91e-06 | BT24: 3.41e-07 | BU24: 7.91e-06 | BV24: 0.0025 | BW24: 4.87e-07 | BX24: 7.91e-06 | BY24: 7.91e-06 | BZ24: 0.0025 | CA24: 2.75e-06 | CB24: 1.25e-07 | CC24: 1.25e-07 | CD24: 1.25e-07
A25: =l_trans!$A23 -> Co n.e.s. | B25: 0 | C25: 0 | D25: 0 | E25: 0 | F25: 0 | G25: 0 | H25: 0 | I25: 0 | J25: 0 | K25: 0 | L25: 0 | M25: 0 | N25: 0 | O25: 0 | P25: 0 | Q25: 0 | R25: 0 | S25: 0 | T25: 0 | U25: 0 | V25: 0 | W25: 0 | X25: 0 | Y25: 0 | Z25: 0 | AA25: 0 | AB25: 0 | AC25: 0 | AD25: 0 | AE25: 0 | AF25: 0 | AG25: 0 | AH25: 0 | AI25: 0 | AJ25: 0 | AK25: 0 | AL25: 0 | AM25: 0 | AN25: 0 | AO25: 0 | AP25: 0 | AQ25: 0 | AR25: 0 | AS25: 0 | AT25: 0 | AU25: 0 | AV25: 0 | AW25: 0 | AX25: 0 | AY25: 0 | AZ25: 0 | BA25: 0 | BB25: 0 | BC25: 0 | BD25: 0 | BE25: 0 | BF25: 0 | BG25: 0 | BH25: 0 | BI25: 0 | BJ25: 0 | BK25: 0 | BL25: 0 | BM25: 0 | BN25: 0 | BO25: 0 | BP25: 0 | BQ25: 0 | BR25: 0 | BS25: 0 | BT25: 0 | BU25: 0 | BV25: 0 | BW25: 0 | BX25: 0 | BY25: 0 | BZ25: 0 | CA25: 0 | CB25: 0 | CC25: 0 | CD25: 0
A26: =l_trans!$A24 -> Cr n.e.s. | B26: 1.5e-05 | C26: 2.92e-05 | D26: 1.18e-05 | E26: 1.18e-05 | F26: 1.55e-05 | G26: 1.51e-05 | H26: 6.68e-06 | I26: 1.55e-05 | J26: 2.54e-05 | K26: 2.54e-05 | L26: 3.27e-05 | M26: 2.54e-05 | N26: 2.54e-05 | O26: 3.27e-05 | P26: 3.27e-05 | Q26: 2.89e-06 | R26: 1.01e-06 | S26: 6.68e-06 | T26: 2.89e-06 | U26: 2.89e-06 | V26: 3.41e-05 | W26: 0.00119 | X26: 0.00119 | Y26: 0.000202 | Z26: 0.000202 | AA26: 3.7e-05 | AB26: 0.000218 | AC26: 0.000109 | AD26: 0.000109 | AE26: 5.79e-05 | AF26: 5.79e-05 | AG26: 0.000168 | AH26: 0.000172 | AI26: 0.000168 | AJ26: 2.87e-06 | AK26: 2.87e-06 | AL26: 2.87e-06 | AM26: 2.87e-06 | AN26: 2.87e-06 | AO26: 2.87e-06 | AP26: 7.32e-05 | AQ26: 7.32e-05 | AR26: 2.87e-06 | AS26: 2.87e-06 | AT26: 7.32e-05 | AU26: 2.87e-06 | AV26: 7.32e-05 | AW26: 7.32e-05 | AX26: 7.32e-05 | AY26: 7.32e-05 | AZ26: 7.32e-05 | BA26: 7.32e-05 | BB26: 7.32e-05 | BC26: 8.14e-06 | BD26: 8.14e-06 | BE26: 8.14e-06 | BF26: 8.14e-06 | BG26: 8.14e-06 | BH26: 7.32e-05 | BI26: 8.14e-06 | BJ26: 9.1e-05 | BK26: 4.51e-06 | BL26: 4.51e-06 | BM26: 4.51e-06 | BN26: 5.24e-06 | BO26: 5.82e-06 | BP26: 7.28e-07 | BQ26: 1.04e-05 | BR26: 0.00016 | BS26: 0.00016 | BT26: 3.41e-05 | BU26: 0.00016 | BV26: 3.34e-05 | BW26: 0.000475 | BX26: 0.00016 | BY26: 0.00016 | BZ26: 3.34e-05 | CA26: 2.69e-06 | CB26: 1.31e-05 | CC26: 1.31e-05 | CD26: 1.31e-05
A27: =l_trans!$A25 -> Cu n.e.s. | B27: 4.19e-05 | C27: 7.71e-05 | D27: 7.05e-05 | E27: 7.05e-05 | F27: 5.4e-05 | G27: 4.95e-06 | H27: 4.28e-05 | I27: 5.4e-05 | J27: 2.76e-05 | K27: 2.76e-05 | L27: 0.000135 | M27: 2.76e-05 | N27: 2.76e-05 | O27: 0.000135 | P27: 0.000135 | Q27: 1.76e-05 | R27: 1.37e-05 | S27: 4.28e-05 | T27: 1.76e-05 | U27: 1.76e-05 | V27: 3.43e-05 | W27: 1.43e-05 | X27: 1.43e-05 | Y27: 1.29e-05 | Z27: 1.29e-05 | AA27: 3.51e-06 | AB27: 5.6e-06 | AC27: 0.000892 | AD27: 0.000892 | AE27: 0.000674 | AF27: 0.000674 | AG27: 0.00263 | AH27: 0.00042 | AI27: 0.00263 | AJ27: 9.48e-05 | AK27: 9.48e-05 | AL27: 9.48e-05 | AM27: 9.48e-05 | AN27: 9.48e-05 | AO27: 9.48e-05 | AP27: 0.000224 | AQ27: 0.000224 | AR27: 9.48e-05 | AS27: 9.48e-05 | AT27: 0.000224 | AU27: 9.48e-05 | AV27: 0.000224 | AW27: 0.000224 | AX27: 0.000224 | AY27: 0.000224 | AZ27: 0.000224 | BA27: 0.000224 | BB27: 0.000224 | BC27: 3.92e-05 | BD27: 3.92e-05 | BE27: 3.92e-05 | BF27: 3.92e-05 | BG27: 3.92e-05 | BH27: 0.000224 | BI27: 3.92e-05 | BJ27: 0.00924 | BK27: 2.02e-05 | BL27: 2.02e-05 | BM27: 2.02e-05 | BN27: 1.25e-05 | BO27: 5.29e-05 | BP27: 5.09e-06 | BQ27: 4.91e-05 | BR27: 9.41e-05 | BS27: 9.41e-05 | BT27: 3.43e-05 | BU27: 9.41e-05 | BV27: 0.00496 | BW27: 2.14e-05 | BX27: 9.41e-05 | BY27: 9.41e-05 | BZ27: 0.00496 | CA27: 5.58e-05 | CB27: 1.32e-05 | CC27: 1.32e-05 | CD27: 1.32e-05
A28: =l_trans!$A26 -> Fe n.e.s. | B28: 0.00122 | C28: 0.000929 | D28: 0.0012 | E28: 0.0012 | F28: 0.00118 | G28: 0.000918 | H28: 0.000789 | I28: 0.00118 | J28: 0.00294 | K28: 0.00294 | L28: 0.00291 | M28: 0.00294 | N28: 0.00294 | O28: 0.00291 | P28: 0.00291 | Q28: 0.000539 | R28: 8.58e-05 | S28: 0.000789 | T28: 0.000539 | U28: 0.000539 | V28: 0.000945 | W28: 0.00176 | X28: 0.00176 | Y28: 0.0024 | Z28: 0.0024 | AA28: 0.000477 | AB28: 0.000766 | AC28: 0.345 | AD28: 0.345 | AE28: 0.0239 | AF28: 0.0239 | AG28: 0.64 | AH28: 0.727 | AI28: 0.64 | AJ28: 0.000849 | AK28: 0.000849 | AL28: 0.000849 | AM28: 0.000849 | AN28: 0.000849 | AO28: 0.000849 | AP28: 0.00175 | AQ28: 0.00175 | AR28: 0.000849 | AS28: 0.000849 | AT28: 0.00175 | AU28: 0.000849 | AV28: 0.00175 | AW28: 0.00175 | AX28: 0.00175 | AY28: 0.00175 | AZ28: 0.00175 | BA28: 0.00175 | BB28: 0.00175 | BC28: 0.000305 | BD28: 0.000305 | BE28: 0.000305 | BF28: 0.000305 | BG28: 0.000305 | BH28: 0.00175 | BI28: 0.000305 | BJ28: 0.0221 | BK28: 0.00148 | BL28: 0.00148 | BM28: 0.00148 | BN28: 0.00031 | BO28: 0.00072 | BP28: 0.000152 | BQ28: 0.00193 | BR28: 0.0016 | BS28: 0.0016 | BT28: 0.000945 | BU28: 0.0016 | BV28: 0.0604 | BW28: 0.00034 | BX28: 0.0016 | BY28: 0.0016 | BZ28: 0.0604 | CA28: 0.000187 | CB28: 0.0132 | CC28: 0.0132 | CD28: 0.0132
A29: =l_trans!$A27 -> Hg n.e.s. | B29: 3.31e-08 | C29: 3.93e-08 | D29: 6.2e-08 | E29: 6.2e-08 | F29: 4.24e-08 | G29: 3.56e-08 | H29: 5.75e-08 | I29: 4.24e-08 | J29: 6.02e-08 | K29: 6.02e-08 | L29: 6.61e-08 | M29: 6.02e-08 | N29: 6.02e-08 | O29: 6.61e-08 | P29: 6.61e-08 | Q29: 2e-08 | R29: 2e-08 | S29: 5.75e-08 | T29: 2e-08 | U29: 2e-08 | V29: 2.13e-07 | W29: 1e-07 | X29: 1e-07 | Y29: 1e-07 | Z29: 1e-07 | AA29: 1e-07 | AB29: 1e-07 | AC29: 2e-07 | AD29: 2e-07 | AE29: 2e-07 | AF29: 2e-07 | AG29: 3.78e-07 | AH29: 2e-07 | AI29: 3.78e-07 | AJ29: 1.98e-08 | AK29: 1.98e-08 | AL29: 1.98e-08 | AM29: 1.98e-08 | AN29: 1.98e-08 | AO29: 1.98e-08 | AP29: 2e-08 | AQ29: 2e-08 | AR29: 1.98e-08 | AS29: 1.98e-08 | AT29: 2e-08 | AU29: 1.98e-08 | AV29: 2e-08 | AW29: 2e-08 | AX29: 2e-08 | AY29: 2e-08 | AZ29: 2e-08 | BA29: 2e-08 | BB29: 2e-08 | BC29: 4.34e-08 | BD29: 4.34e-08 | BE29: 4.34e-08 | BF29: 4.34e-08 | BG29: 4.34e-08 | BH29: 2e-08 | BI29: 4.34e-08 | BJ29: 2.12e-07 | BK29: 2.62e-07 | BL29: 2.62e-07 | BM29: 2.62e-07 | BN29: 2e-08 | BO29: 2e-08 | BP29: 2e-08 | BQ29: 6.67e-07 | BR29: 4.9e-07 | BS29: 4.9e-07 | BT29: 2.13e-07 | BU29: 4.9e-07 | BV29: 0.000916 | BW29: 8.47e-08 | BX29: 4.9e-07 | BY29: 4.9e-07 | BZ29: 0.000916 | CA29: 3.96e-08 | CB29: 0 | CC29: 0 | CD29: 0
... A36: =l_trans!$A34 -> Inertes n.e.s. | B36: 0.027227333 | C36: 0.19776949 | D36: 0.21922283 | E36: 0.21922283 | F36: 0.10147719 | G36: 0.12392346 | H36: 0.11804361 | I36: 0.10147719 | J36: 0.091896896 | K36: 0.091896896 | L36: 0.088459372 | M36: 0.091896896 | N36: 0.091896896 | O36: 0.088459372 | P36: 0.088459372 | Q36: 0.028075553 | R36: 0.006405156 | S36: 0.11804361 | T36: 0.028075553 | U36: 0.028075553 | V36: 0.08007832 | W36: 0.88225642 | X36: 0.88225642 | Y36: 0.87628529 | Z36: 0.87628529 | AA36: 0.88798019 | AB36: 0.88645288 | AC36: 0.008363179 | AD36: 0.008363179 | AE36: 0.070429912 | AF36: 0.070429912 | AG36: 0.30429671 | AH36: 0.05090181 | AI36: 0.30429671 | AJ36: 0.0039959558 | AK36: 0.0039959558 | AL36: 0.0039959558 | AM36: 0.0039959558 | AN36: 0.0039959558 | AO36: 0.0039959558 | AP36: 0.012329173 | AQ36: 0.012329173 | AR36: 0.0039959558 | AS36: 0.0039959558 | AT36: 0.012329173 | AU36: 0.0039959558 | AV36: 0.012329173 | AW36: 0.012329173 | AX36: 0.012329173 | AY36: 0.012329173 | AZ36: 0.012329173 | BA36: 0.012329173 | BB36: 0.012329173 | BC36: 0.039748362 | BD36: 0.039748362 | BE36: 0.039748362 | BF36: 0.039748362 | BG36: 0.039748362 | BH36: 0.012329173 | BI36: 0.039748362 | BJ36: 0.17299426 | BK36: 0.19675789 | BL36: 0.19675789 | BM36: 0.19675789 | BN36: 0.0087062984 | BO36: 0.015268619 | BP36: 0.047945868 | BQ36: 0.18565743 | BR36: 0.8394497 | BS36: 0.8394497 | BT36: 0.08007832 | BU36: 0.8394497 | BV36: 0.4362652 | BW36: 0.017932129 | BX36: 0.8394497 | BY36: 0.8394497 | BZ36: 0.4362652 | CA36: 0.059514046 | CB36: 0.88150807 | CC36: 0.88150807 | CD36: 0.88150807
A37: =l_trans!$A35 -> N2
A40: =l_trans!$A40 -> Be n.e.s.
A41: =l_trans!$A41 -> B n.e.s.
A42: =l_trans!$A42 -> Ne n.e.s.
A43: =l_trans!$A43 -> Si n.e.s.
A44: =l_trans!$A44 -> Sc n.e.s.
A45: =l_trans!$A45 -> Ti n.e.s.
A46: =l_trans!$A46 -> V n.e.s.
A47: =l_trans!$A$48 -> Ge n.e.s.
A48: =l_trans!$A$49 -> Se n.e.s.
A49: =l_trans!$A$50 -> Br n.e.s.
A50: =l_trans!$A$51 -> Kr n.e.s.
A51: =l_trans!$A$52 -> Rb n.e.s.
...

Sheet cons
A1: id | B1: =l_trans!A3 -> CO2 | C1: CH4 | D1: C n.e.s. | E1: C_bio | F1: C_fossil | G1: Ca n.e.s. | H1: Cl n.e.s. | I1: F n.e.s. | J1: H n.e.s. | K1: K n.e.s. | L1: N n.e.s. | M1: Na n.e.s. | N1: O n.e.s. | O1: P n.e.s. | P1: S n.e.s. | Q1: Ag n.e.s. | R1: Al n.e.s. | S1: Ar n.e.s. | T1: As n.e.s. | U1: Cd n.e.s. | V1: Co n.e.s. | W1: Cr n.e.s. | X1: Cu n.e.s. | Y1: Fe n.e.s. | Z1: Hg n.e.s. | AA1: Mg n.e.s. | AB1: Mn n.e.s. | AC1: Mo n.e.s. | AD1: Ni n.e.s. | AE1: Pb n.e.s. | AF1: Zn n.e.s. | AG1: Inertes n.e.s. | AH1: N2 | AO1: =l_trans!$A$40 -> Be n.e.s. | AP1: =l_trans!$A$41 -> B n.e.s. | AQ1: =l_trans!$A$42 -> Ne n.e.s. | AR1: =l_trans!$A$43 -> Si n.e.s. | AS1: =l_trans!$A$44 -> Sc n.e.s. | AT1: =l_trans!$A$45 -> Ti n.e.s. | AU1: =l_trans!$A$46 -> V n.e.s. | AV1: =l_trans!$A$47 -> Ga n.e.s. | AW1: =l_trans!$A$48 -> Ge n.e.s. | AX1: =l_trans!$A$49 -> Se n.e.s. | AY1: =l_trans!$A$50 -> Br n.e.s. | AZ1: =l_trans!$A$51 -> Kr n.e.s. | BA1: =l_trans!$A$52 -> Rb n.e.s. | BB1: =l_trans!$A$53 -> Sr n.e.s. | BC1: =l_trans!$A$54 -> Y n.e.s. | BD1: =l_trans!$A$55 -> Zr n.e.s. | BE1: =l_trans!$A$56 -> Nb n.e.s. | BF1: =l_trans!$A$57 -> Tc n.e.s. | BG1: =l_trans!$A$58 -> Ru n.e.s. | BH1: =l_trans!$A$59 -> Rh n.e.s. | BI1: =l_trans!$A$60 -> Pd n.e.s. | BJ1: =l_trans!$A$61 -> In n.e.s. | BK1: =l_trans!$A$62 -> Sn n.e.s. | BL1: =l_trans!$A$63 -> Sb n.e.s. | BM1: =l_trans!$A$64 -> Te n.e.s. | BN1: =l_trans!$A$65 -> I n.e.s. | BO1: =l_trans!$A$66 -> Xe n.e.s. | BP1: =l_trans!$A$67 -> Cs n.e.s. | BQ1: =l_trans!$A$68 -> Ba n.e.s. | BR1: =l_trans!$A$69 -> La n.e.s. | BS1: =l_trans!$A$70 -> Ce n.e.s. | BT1: =l_trans!$A$71 -> Pr n.e.s. | BU1: =l_trans!$A$72 -> Nd n.e.s. | BV1: =l_trans!$A$73 -> Pm n.e.s. | BW1: =l_trans!$A$74 -> Sm n.e.s. | BX1: =l_trans!$A$75 -> Eu n.e.s. | BY1: =l_trans!$A$76 -> Gd n.e.s. | BZ1: =l_trans!$A$77 -> Tb n.e.s. | CA1: =l_trans!$A$78 -> Dy n.e.s. | CB1: =l_trans!$A$79 -> Ho n.e.s. | CC1: =l_trans!$A$80 -> Er n.e.s. | CD1: =l_trans!$A$81 -> Tm n.e.s. | CE1: =l_trans!$A$82 -> Yb n.e.s. | CF1: =l_trans!$A$83 -> Lu n.e.s. | CG1: =l_trans!$A$84 -> Hf n.e.s. | CH1: =l_trans!$A$85 -> Ta n.e.s. | CI1: =l_trans!$A$86 -> W n.e.s. | CJ1: =l_trans!$A$87 -> Re n.e.s. | CK1: =l_trans!$A$88 -> Os n.e.s. | CL1: =l_trans!$A$89 -> Ir n.e.s. | CM1: =l_trans!$A$90 -> Pt n.e.s. | CN1: =l_trans!$A$91 -> Au n.e.s. | CO1: =l_trans!$A$92 -> Tl n.e.s. | CP1: =l_trans!$A$93 -> Bi n.e.s. | CQ1: =l_trans!$A$94 -> Po n.e.s. | CR1: =l_trans!$A$95 -> At n.e.s. | CS1: =l_trans!$A$96 -> Rn n.e.s. | CT1: =l_trans!$A$97 -> Fr n.e.s. | CU1: =l_trans!$A$98 -> Ra n.e.s. | CV1: =l_trans!$A$99 -> Ac n.e.s. | CW1: =l_trans!$A$100 -> Th n.e.s. | CX1: =l_trans!$A$101 -> Pa n.e.s. | CY1: =l_trans!$A$102 -> U n.e.s. | CZ1: =l_trans!$A$103 -> Np n.e.s. | DA1: =l_trans!$A$104 -> Pu n.e.s. | DB1: =l_trans!$A$105 -> Am n.e.s. | DC1: =l_trans!$A$106 -> Cm n.e.s. | DD1: =l_trans!$A$107 -> Bk n.e.s. | DE1: =l_trans!$A$108 -> Cf n.e.s. | DF1: =l_trans!$A$109 -> Es n.e.s. | DG1: =l_trans!$A$110 -> Fm n.e.s. | DH1: =l_trans!$A$111 -> Md n.e.s. | DI1: =l_trans!$A$112 -> No n.e.s. | DJ1: =l_trans!$A$113 -> Lr n.e.s. | DK1: =l_trans!$A$114 -> Rf n.e.s. | DL1: =l_trans!$A$115 -> Db n.e.s. | DM1: =l_trans!$A$116 -> Sg n.e.s. | DN1: =l_trans!$A$117 -> Bh n.e.s. | DO1: =l_trans!$A$118 -> Hs n.e.s. | DP1: =l_trans!$A$119 -> Mt n.e.s. | DQ1: =l_trans!$A$120 -> Ds n.e.s. | DR1: =l_trans!$A$121 -> Rg n.e.s. | DS1: =l_trans!$A$122 -> Cn n.e.s. | DT1: =l_trans!$A$123 -> Nh n.e.s. | DU1: =l_trans!$A$124 -> Fl n.e.s. | DV1: =l_trans!$A$125 -> Mc n.e.s. | DW1: =l_trans!$A$126 -> Lv n.e.s. | DX1: =l_trans!$A$127 -> Ts n.e.s. | DY1: =l_trans!$A$128 -> Og n.e.s. | DZ1: =l_trans!$A$129 | EA1: =l_trans!$A$130 | EB1: =l_trans!$A$131 | EC1: =l_trans!$A$132 | ED1: =l_trans!$A$133 | EE1: =l_trans!$A$134 | EF1: =l_trans!$A$135 | EG1: =l_trans!$A$136 | EH1: =l_trans!$A$137 | EI1: =l_trans!$A$138 | EJ1: =l_trans!$A$139 | EK1: =l_trans!$A$140 | EL1: =l_trans!$A$141 | EM1: =l_trans!$A$142 | EN1: =l_trans!$A$143 | EO1: =l_trans!$A$144 | EP1: =l_trans!$A$145 | EQ1: =l_trans!$A$146 | ER1: =l_trans!$A$147 | ES1: =l_trans!$A$148 | ET1: =l_trans!$A$149 | EU1: =l_trans!$A$150 | EV1: =l_trans!$A$151 | EW1: =l_trans!$A$152 | EX1: =l_trans!$A$153 | EY1: =l_trans!$A$154 | EZ1: =l_trans!$A$155 | FA1: =l_trans!$A$156 | FB1: =l_trans!$A$157 | FC1: =l_trans!$A$158 | FD1: =l_trans!$A$159 | FE1: =l_trans!$A$160 | FF1: =l_trans!$A$161 | FG1: =l_trans!$A$162 | FH1: =l_trans!$A$163 | FI1: =l_trans!$A$164 | FJ1: =l_trans!$A$165 | FK1: =l_trans!$A$166 | FL1: =l_trans!$A$167 | FM1: =l_trans!$A$168 | FN1: =l_trans!$A$169 | FO1: =l_trans!$A$170 | FP1: =l_trans!$A$171 | FQ1: =l_trans!$A$172 | FR1: =l_trans!$A$173 | FS1: =l_trans!$A$174 | FT1: =l_trans!$A$175 | FU1: =l_trans!$A$176 | FV1: =l_trans!$A$177 | FW1: =l_trans!$A$178 | FX1: =l_trans!$A$179 | FY1: =l_trans!$A$180 | FZ1: =l_trans!$A$181 | GA1: =l_trans!$A$182 | GB1: =l_trans!$A$183 | GC1: =l_trans!$A$184 | GD1: =l_trans!$A$185 | GE1: =l_trans!$A$186 | GF1: =l_trans!$A$187 | GG1: =l_trans!$A$188 | GH1: =l_trans!$A$189 | GI1: =l_trans!$A$190 | GJ1: =l_trans!$A$191 | GK1: =l_trans!$A$192 | GL1: =l_trans!$A$193 | GM1: =l_trans!$A$194 | GN1: =l_trans!$A$195 | GO1: =l_trans!$A$196 | GP1: =l_trans!$A$197 | GQ1: =l_trans!$A$198 | GR1: =l_trans!$A$199 | GS1: =l_trans!$A$200 | GT1: =l_trans!$A$201 | GU1: =l_trans!$A$202
A2: =l_cons!$A3 -> unknown_elements | AG2: 1
A3: =l_cons!$A4 -> C
A4: =l_cons!$A5 -> Ca
A5: =l_cons!$A6 -> Cl
A6: =l_cons!$A7 -> F
A7: =l_cons!$A8 -> H
A8: =l_cons!$A9 -> K
A9: =l_cons!$A10 -> N
A10: =l_cons!$A11 -> Na
A11: =l_cons!$A12 -> O
A12: =l_cons!$A13 -> P
A13: =l_cons!$A14 -> S
A14: =l_cons!$A15 -> Ag
... A37: =l_cons!$A38 -> Ti
A38: =l_cons!$A39 -> V | B38: =l_trans!$A40 -> Be n.e.s.
A39: =l_cons!$A40 -> Ga | B39: =l_trans!$A41 -> B n.e.s.
A40: =l_cons!$A41 -> Ge | B40: =l_trans!$A42 -> Ne n.e.s.
A41: =l_cons!$A42 -> Se | B41: =l_trans!$A43 -> Si n.e.s.
A42: =l_cons!$A43 -> Br | B42: =l_trans!$A44 -> Sc n.e.s.
A43: =l_cons!$A44 -> Kr | B43: =l_trans!$A45 -> Ti n.e.s.
A44: =l_cons!$A45 -> Rb | B44: =l_trans!$A46 -> V n.e.s.
A45: =l_cons!$A46 -> Sr | B45: =l_trans!$A47 -> Ga n.e.s.
A46: =l_cons!$A47 -> Y | B46: =l_trans!$A48 -> Ge n.e.s.
A47: =l_cons!$A48 -> Zr | B47: =l_trans!$A49 -> Se n.e.s.
A48: =l_cons!$A49 -> Nb | B48: =l_trans!$A50 -> Br n.e.s.
A49: =l_cons!$A50 -> Tc | B49: =l_trans!$A51 -> Kr n.e.s.
... A138: =l_cons!$A139 | B138: =l_trans!$A140
A139: =l_cons!$A140
A140: =l_cons!$A141
A141: =l_cons!$A142
A142: =l_cons!$A143
A143: =l_cons!$A144
A144: =l_cons!$A145
A145: =l_cons!$A146
A146: =l_cons!$A147
A147: =l_cons!$A148
A148: =l_cons!$A149
A149: =l_cons!$A150
A150: =l_cons!$A151
...

Sheet cons_permol
A1: substance | B1: element | C1: molar composition
A2: CO2 | B2: C | C2: 1
A3: CO2 | B3: O | C3: 2
A4: CH4 | B4: C | C4: 1
A5: CH4 | B5: H | C5: 4
A6: N2O | B6: N | C6: 2
A7: N2O | B7: O | C7: 1
A8: NH3 | B8: N | C8: 1
A9: NH3 | B9: H | C9: 3
A10: N2 | B10: N | C10: 2
A11: C_bio | B11: C | C11: 1
A12: C_fossil | B12: C | C12: 1
A13: H n.e.s. | B13: H | C13: 1
... A130: Og n.e.s. | B130: Og | C130: 1

Sheet meta_process
A1: act_id | B1: sub_activity | C1: reference_input_flow | D1: u | E1: v
A2: compost_overall | B2: aggr_1 | C2: collecte_orga | D2: 1
A3: compost_overall | B3: pre_screen_1 | C3: gisement_coll_orga | E3: -1
A4: compost_overall | B4: pre_screen_2 | C4: Overs_1 | E4: -1
A5: compost_overall | B5: mixing | C5: Unders_1 | E5: -1
A6: compost_overall | B6: mixing | C6: Unders_2 | E6: -1

Sheet foreground
B1: Destination activity ID | C1: index | D1: Emission ID | I1: Use (U) | J1: Supply (V) | K1: Emission (F) | O1: Comments | P1: Source | Q1: Uncertainty
B2: compost_overall | C2: collecte_orga | I2: 1

Sheet background_technosphere
A1: index | B1: activityId | C1: productId | D1: activityNameId | E1: activityName | F1: productName | G1: geography | H1: unitName | I1: price | J1: priceUnit

Sheet background_biosphere
A1: emissionId | B1: emissionName | C1: comp | D1: subcomp | E1: unitName
A2: d21da01e-f96f-4db5-9746-7b70db8a1f2c | B2: 1,4-Butanediol | C2: air | D2: low population density, long-term | E2: kg
A3: 90653a29-2f53-4b1b-88bd-9ae2fe64a8d6 | B3: 1,4-Butanediol | C3: air | D3: lower stratosphere + upper troposphere | E3: kg
A4: 83bafcf1-2f2e-4a32-89a0-f1f16ca10626 | B4: 1,4-Butanediol | C4: air | D4: non-urban air or from high stacks | E4: kg
A5: 09db39be-d9a6-4fc3-8d25-1f80b23e9131 | B5: 1,4-Butanediol | C5: air | D5: unspecified | E5: kg
A6: 38a622c6-f086-4763-a952-7c6b3b1c42ba | B6: 1,4-Butanediol | C6: air | D6: urban air close to ground | E6: kg
A7: 9dd01d5b-3677-4822-9cd4-36d21b0e23d1 | B7: 1-Pentanol | C7: air | D7: low population density, long-term | E7: kg
A8: b78e77cb-7636-4420-855e-17239984f8b3 | B8: 1-Pentanol | C8: air | D8: lower stratosphere + upper troposphere | E8: kg
A9: cc9a442f-c96a-4bdc-990d-8b58f72b4e07 | B9: 1-Pentanol | C9: air | D9: non-urban air or from high stacks | E9: kg
A10: 048baf1e-6cdc-44a5-92e2-32d15ff54885 | B10: 1-Pentanol | C10: air | D10: unspecified | E10: kg
A11: 541a823c-0aad-4dc4-9123-d4af4647d942 | B11: 1-Pentanol | C11: air | D11: urban air close to ground | E11: kg
A12: 47a8dfb8-f1e5-4460-b7ca-eeea1ca44596 | B12: 1-Pentene | C12: air | D12: low population density, long-term | E12: kg
... A4244: 365dffb2-9e7a-44fa-a512-8c851fc7094c | B4244: t-Butylamine | C4244: water | D4244: unspecified | E4244: kg

Sheet lay_f_trans
A1: id production factor | B1: {=IF(TRANSPOSE(l_fp!A3:A203)=0,"",TRANSPOSE(l_fp!A3:A203))} | C1: 73ed05cc-9727-4abf-9516-4b5c0fe54a16 | D1: b53d3744-3629-4219-be20-980865e54031 | E1: 9990b51b-7023-4700-bca0-1a32ef921f74 | F1: d068f3e2-b033-417b-a359-ca4f25da9731 | G1: e3f5fd63-7dcb-41f1-9b8a-a48a8d68bc65 | H1: af01e564-f816-4906-bd4f-b7c932f926b9
A4: =l_trans!$A$3 -> CO2
A5: =l_trans!$A$4 -> CH4
A6: =l_trans!$A$26 -> Fe n.e.s.
A7: =l_trans #REF! -> #VALUE!
A8: =l_trans!$A$5 -> C n.e.s.
A9: =l_trans!$A$6 -> C_bio
A10: =l_trans!$A$7 -> C_fossil
A11: =l_trans!$A$8 -> Ca n.e.s.
A12: =l_trans!$A$9 -> Cl n.e.s.
A13: =l_trans!$A$10 -> F n.e.s.
A14: =l_trans!$A$11 -> H n.e.s.
A15: =l_trans!$A$12 -> K n.e.s.
A16: =l_trans!$A$13 -> N n.e.s.
A17: =l_trans!$A$14 -> Na n.e.s.
A18: =l_trans!$A$15 -> O n.e.s.
A19: =l_trans!$A$16 -> P n.e.s.
A20: =l_trans!$A$17 -> S n.e.s.
A21: =l_trans!$A$18 -> Ag n.e.s.
A22: =l_trans!$A$19 -> Al n.e.s.
A23: =l_trans!$A$20 -> Ar n.e.s.
A24: =l_trans!$A$21 -> As n.e.s.
A25: =l_trans!$A$22 -> Cd n.e.s.
A26: =l_trans!$A$23 -> Co n.e.s.
A27: =l_trans!$A$24 -> Cr n.e.s.
A28: =l_trans!$A$25 -> Cu n.e.s.
A29: =l_trans #REF! -> #VALUE!
A30: =l_trans!$A$27 -> Hg n.e.s.
A31: =l_trans!$A$28 -> Mg n.e.s.
A32: =l_trans!$A$29 -> Mn n.e.s.
A33: =l_trans!$A$30 -> Mo n.e.s.
A34: =l_trans!$A$31 -> Ni n.e.s.
A35: =l_trans!$A$32 -> Pb n.e.s.
A36: =l_trans!$A$33 -> Zn n.e.s.
A37: =l_trans!$A$34 -> Inertes n.e.s.
A38: =l_trans #REF! -> #VALUE!
A39: =l_trans!$A$35 -> N2
A40: =l_trans!$A$40 -> Be n.e.s.
A41: =l_trans!$A$41 -> B n.e.s.
A42: =l_trans!$A$42 -> Ne n.e.s.
...

Sheet y
A1: =l_goods!$A$1 -> productId | C1: final_demand

Sheet tr
A1: cons_in | B1: trans_in | C1: goods_in ID | E1: act | F1: trans_out (opt.) | G1: out ID | I1: value | J1: order (opt.) | K1: Functional output (default=True) | L1: source | M1: uncertainty | N1: comment
C2: A-01 | E2: Aggrégation Recyc-Qc vers T2_SWOLF GLO | G2: T2-08 | I2: 1 | J2: 1
C3: A-02 | E3: Aggrégation Recyc-Qc vers T2_SWOLF GLO | G3: T2-08 | I3: 1 | J3: 1 | N3: PASSER DIRECTEMENT DE RECYC-QC À T25-..
C4: A-03 | E4: Aggrégation Recyc-Qc vers T2_SWOLF GLO | G4: T2-11 | I4: 1 | J4: 1 | N4: au final : modification de la gestion de la séquence permet les goods in goods in goods réutilisés à travers les étapes d'une même activité
C5: A-04 | E5: Aggrégation Recyc-Qc vers T2_SWOLF GLO | G5: T2-11 | I5: 1 | J5: 1
C6: A-05 | E6: Aggrégation Recyc-Qc vers T2_SWOLF GLO | G6: T2-08 | I6: 1 | J6: 1
C7: A-06 | E7: Aggrégation Recyc-Qc vers T2_SWOLF GLO | G7: T2-10 | I7: 1 | J7: 1
C8: A-07 | E8: Aggrégation Recyc-Qc vers T2_SWOLF GLO | G8: T2-12 | I8: 1 | J8: 1
C9: A-08 | E9: Aggrégation Recyc-Qc vers T2_SWOLF GLO | G9: T2-10 | I9: 1 | J9: 1
C10: A-09 | E10: Aggrégation Recyc-Qc vers T2_SWOLF GLO | G10: T2-15 | I10: 1 | J10: 1
C11: B-01 | E11: Aggrégation Recyc-Qc vers T2_SWOLF GLO | G11: T2-09 | I11: 1 | J11: 1
C12: B-02 | E12: Aggrégation Recyc-Qc vers T2_SWOLF GLO | G12: T2-14 | I12: 1 | J12: 1
C13: B-03 | E13: Aggrégation Recyc-Qc vers T2_SWOLF GLO | G13: T2-14 | I13: 1 | J13: 1
C14: B-04 | E14: Aggrégation Recyc-Qc vers T2_SWOLF GLO | G14: T2-13 | I14: 1 | J14: 1
C15: B-05 | E15: Aggrégation Recyc-Qc vers T2_SWOLF GLO | G15: T2-13 | I15: 1 | J15: 1
C16: B-06 | E16: Aggrégation Recyc-Qc vers T2_SWOLF GLO | G16: T2-15 | I16: 1 | J16: 1
... C68: G-01 | E68: Aggrégation Recyc-Qc vers T2_SWOLF GLO | G68: T2-20 | I68: 0.1274 | J68: 1
C69: G-01 | E69: Aggrégation Recyc-Qc vers T2_SWOLF GLO | G69: T2-28 | I69: =1-I68 -> 0.8726 | J69: 1
C70: G-02 | E70: Aggrégation Recyc-Qc vers T2_SWOLF GLO | G70: T2-28 | I70: 1 | J70: 1
C71: H-01 | E71: Aggrégation Recyc-Qc vers T2_SWOLF GLO | G71: T2-27 | I71: 1 | J71: 1
C72: H-02 | E72: Aggrégation Recyc-Qc vers T2_SWOLF GLO | G72: T2-27 | I72: 1 | J72: 1
C73: H-03 | E73: Aggrégation Recyc-Qc vers T2_SWOLF GLO | G73: T2-05 | I73: 1 | J73: 1
C74: H-04 | E74: Aggrégation Recyc-Qc vers T2_SWOLF GLO | G74: T2-27 | I74: 1 | J74: 1
C75: H-05 | E75: Aggrégation Recyc-Qc vers T2_SWOLF GLO | G75: T2-27 | I75: 1 | J75: 1
C76: H-06 | E76: Aggrégation Recyc-Qc vers T2_SWOLF GLO | G76: T2-06 | I76: 1 | J76: 1
C77: G-03 | E77: Aggrégation Recyc-Qc vers T2_SWOLF GLO | G77: T2-27 | I77: 1 | J77: 1
C78: G-04 | E78: Aggrégation Recyc-Qc vers T2_SWOLF GLO | G78: T2-27 | I78: 1 | J78: 1
C79: H-07 | E79: Aggrégation Recyc-Qc vers T2_SWOLF GLO | G79: T2-27 | I79: 1 | J79: 1
C80: H-08 | E80: Aggrégation Recyc-Qc vers T2_SWOLF GLO | G80: T2-07 | I80: 1 | J80: 1
C81: H-09 | E81: Aggrégation Recyc-Qc vers T2_SWOLF GLO | G81: T2-27 | I81: 1 | J81: 1
... C127: T25-13 | E127: Aggrégation Recyc-Qc vers T2_SWOLF GLO | G127: gisement_coll_orga | I127: 1 | J127: 3
C132: T25-01 | E132: Pre_Screening_1 QC | G132: overs_1 | I132: 0.02 | J132: 1 | K132: False | N132: TODO : s'assurer que overs_1, unders_1 contiennent les T25-1 à 13 encore :soient des goods_in_goods
C133: T25-01 | E133: Pre_Screening_1 QC | G133: unders_1 | I133: 1 | J133: 2 | K133: False
C134: T25-02 | E134: Pre_Screening_1 QC | G134: overs_1 | I134: 0.02 | J134: 1 | K134: False
C135: T25-02 | E135: Pre_Screening_1 QC | G135: unders_1 | I135: 1 | J135: 2 | K135: False
C136: T25-03 | E136: Pre_Screening_1 QC | G136: overs_1 | I136: 0.95 | J136: 1 | K136: False
C137: T25-03 | E137: Pre_Screening_1 QC | G137: unders_1 | I137: 1 | J137: 2 | K137: False
C138: T25-04 | E138: Pre_Screening_1 QC | G138: overs_1 | I138: 0.02 | J138: 1 | K138: False
C139: T25-04 | E139: Pre_Screening_1 QC | G139: unders_1 | I139: 1 | J139: 2 | K139: False
C140: T25-05 | E140: Pre_Screening_1 QC | G140: overs_1 | I140: 0.95 | J140: 1 | K140: False
...

Sheet te
A1: activityId | C1: determined flow ID (economic or elementary) | E1: determined flow property | F1: value | G1: reference flow ID | I1: property [default = reference property] | J1: functional [default=False] | K1: order [default=0] | L1: source | M1: uncertainty | N1: comment
A2: pre_screen_1 | C2: electricity | E2: à valider (optionel?) | F2: 0.0011 | G2: overs_1 | K2: 3 | L2: Komilis et al, 2014 | N2: Trommel, unit : kWh/kg
A3: pre_screen_1 | C3: electricity | E3: à valider (optionel?) | F3: =1.1/1000 -> 0.0011 | G3: unders_1 | K3: 3 | L3: Komilis et al, 2014 | N3: Trommel, unit : kWh/kg
A4: pre_screen_1 | C4: composting_facility_open | E4: à valider (optionel?) | F4: =4*10^-9 -> 4e-09 | G4: overs_1 | K4: 3 | L4: ecoinvent | N4: unit / kg
A5: pre_screen_1 | C5: composting_facility_open | E5: à valider (optionel?) | F5: =4*10^-9 -> 4e-09 | G5: unders_1 | K5: 3 | L5: ecoinvent | N5: unit / kg
E6: à valider (optionel?)
A7: pre_screen_2 | C7: electricity | E7: à valider (optionel?) | F7: =0.0011 -> 0.0011 | G7: overs_1 | K7: 0 | L7: Komilis et al, 2014 | N7: Trommel, unit : kWh/kg
A8: pre_screen_2 | C8: diesel | E8: à valider (optionel?) | F8: =10.2*0.13/1000 -> 0.001326 | G8: unders_2 | K8: 3 | L8: Komilis et al, 2014 | N8: Tub grinder, unit : 10,2 kWh / t & 0,13 L diesel / kWh / kg
A9: pre_screen_2 | C9: electricity | E9: à valider (optionel?) | F9: =15/1000 -> 0.015 | G9: unders_2 | K9: 3 | L9: Komilis et al, 2014 | N9: Hammermill, unit : kWh/kg
E10: à valider (optionel?)
A11: act_composting | C11: 73ed05cc-9727-4abf-9516-4b5c0fe54a16 | E11: à valider (optionel?) | F11: 1 | G11: off_gas_1 | I11: CO2 | K11: 6
A12: act_composting | C12: b53d3744-3629-4219-be20-980865e54031 | E12: à valider (optionel?) | F12: 1 | G12: off_gas_1 | I12: CH4 | K12: 6
A13: act_composting | C13: 9990b51b-7023-4700-bca0-1a32ef921f74 | E13: à valider (optionel?) | F13: 1 | G13: off_gas_1 | I13: NH3 | K13: 6
A14: act_composting | C14: d068f3e2-b033-417b-a359-ca4f25da9731 | E14: à valider (optionel?) | F14: 1 | G14: off_gas_1 | I14: N2O | K14: 6
A15: act_composting | C15: e3f5fd63-7dcb-41f1-9b8a-a48a8d68bc65 | E15: à valider (optionel?) | F15: 1 | G15: off_gas_1 | I15: N2 | K15: 6
A16: act_composting | C16: oxygen_from_airtank | E16: à valider (optionel?) | F16: 0.6 | G16: off_gas_1 | I16: O | J16: FALSE | K16: 2
E17: à valider (optionel?)
A18: post_screen | C18: electricity | E18: à valider (optionel?) | F18: =0.8/1000 -> 0.0008 | G18: compost_1 | K18: 3 | L18: Komilis et al, 2014 | N18: Trommel, unit : KWh/kg
A19: post_screen | C19: diesel | E19: à valider (optionel?) | F19: 0.00022 | G19: compost_1 | K19: 3
E20: à valider (optionel?)
A21: substitution_npk | C21: fertiliser_N | E21: à valider (optionel?) | F21: -0.15 | G21: compost_final | I21: N | K21: 6
A22: substitution_npk | C22: fertiliser_P2O5 | E22: à valider (optionel?) | F22: -1 | G22: compost_final | I22: P | K22: 6
K28: 4.575989e+06
K29: 2.006333e+07
K31: =4576 -> 4576
K32: 20063
K33: =K31+K32 -> 24639

Sheet version
A1: V 2.0.0
B2: te can express a ratio based on other properties than the reference
C3: e.g.: inputs of water (the dependent flow) such that we have 4 (value) moles_H (dependent flow property) per moles_C (reference flow property) of methane emissions (reference flow)
B5: te of an activity can be ascribed an order of operation
